Namespace(actions='*', architecture='3,3', batch_size=4096, bone_length_term=True, by_subject=False, causal=False, channels=1024, checkpoint='checkpoint_receptive_9', checkpoint_frequency=10, data_augmentation=True, dataset='h36m', dense=False, disable_optimizations=False, downsample=1, dropout=0.25, epochs=80, evaluate='', export_training_curves=False, keypoints='cpn_ft_h36m_dbb', learning_rate=0.001, linear_projection=False, lr_decay=0.95, no_eval=False, no_proj=False, render=False, resume='', stride=1, subjects_test='S9,S11', subjects_train='S1,S5,S6,S7,S8', subjects_unlabeled='', subset=1, test_time_augmentation=True, viz_action=None, viz_bitrate=3000, viz_camera=0, viz_downsample=1, viz_export=None, viz_limit=-1, viz_no_ground_truth=False, viz_output=None, viz_size=5, viz_skip=0, viz_subject=None, viz_video=None, warmup=1)
Loading dataset...
Preparing data...
Loading 2D detections...
INFO: Receptive field: 9 frames
INFO: Trainable parameter count: 4357171
Traceback (most recent call last):
  File "run.py", line 201, in <module>
    model_pos = model_pos.cuda()
  File "/home/huanx/anaconda3/envs/poseaug/lib/python3.6/site-packages/torch/nn/modules/module.py", line 637, in cuda
    return self._apply(lambda t: t.cuda(device))
  File "/home/huanx/anaconda3/envs/poseaug/lib/python3.6/site-packages/torch/nn/modules/module.py", line 530, in _apply
    module._apply(fn)
  File "/home/huanx/anaconda3/envs/poseaug/lib/python3.6/site-packages/torch/nn/modules/module.py", line 552, in _apply
    param_applied = fn(param)
  File "/home/huanx/anaconda3/envs/poseaug/lib/python3.6/site-packages/torch/nn/modules/module.py", line 637, in <lambda>
    return self._apply(lambda t: t.cuda(device))
RuntimeError: CUDA error: out of memory
CUDA kernel errors might be asynchronously reported at some other API call,so the stacktrace below might be incorrect.
For debugging consider passing CUDA_LAUNCH_BLOCKING=1.
